Workbook

Sheet Ringkasan
A1: Ringkasan Perbandingan Pengadaan BBPVP Bandung
A2: Perbandingan snapshot data 5 Agustus 2026 dan 12 Agustus 2026 berdasarkan Kode RUP.
A4: Indikator | B4: 5 Agustus 2026 | C4: 12 Agustus 2026 | D4: Perubahan | F4: Kategori Perubahan | G4: Jumlah | H4: Keterangan
A5: Jumlah Paket | B5: =COUNTA(Data_05_Agu!A4:A1000) -> 149 | C5: =COUNTA(Data_12_Agu!A4:A1000) -> 156 | D5: =C5-B5 -> 7 | F5: BARU DI 12 Agu | G5: =COUNTIF(Perbandingan!B:B,F5) -> 9 | H5: Kode RUP hanya ada pada snapshot 12 Agustus
A6: Total Pagu (Rp) | B6: =SUM(Data_05_Agu!G4:G1000) -> 15456001028 | C6: =SUM(Data_12_Agu!G4:G1000) -> 15005184004 | D6: =C6-B6 -> -450817024 | F6: TIDAK MUNCUL DI 12 Agu | G6: =COUNTIF(Perbandingan!B:B,F6) -> 2 | H6: Kode RUP ada pada 5 Agustus tetapi tidak ada pada 12 Agustus
A7: Total Realisasi (Rp) | B7: =SUM(Data_05_Agu!H4:H1000) -> 6.7493934e+09 | C7: =SUM(Data_12_Agu!H4:H1000) -> 5802553331 | D7: =C7-B7 -> -9.4684006e+08 | F7: BERUBAH | G7: =COUNTIF(Perbandingan!B:B,F7) -> 41 | H7: Kode RUP sama, minimal satu field berubah
A8: Realisasi terhadap Pagu | B8: =IFERROR(B7/B6,0) -> 0.43668433 | C8: =IFERROR(C7/C6,0) -> 0.38670324 | D8: =C8-B8 -> -0.049981082 | F8: TETAP | G8: =COUNTIF(Perbandingan!B:B,F8) -> 106 | H8: Tidak ada perubahan data
A11: Status | B11: 5 Agustus | C11: 12 Agustus | F11: Metode | G11: 5 Agustus | H11: 12 Agustus
A12: BELUM REALISASI | B12: =COUNTIF(Data_05_Agu!F:F,A12) -> 118 | C12: =COUNTIF(Data_12_Agu!F:F,A12) -> 133 | F12: E-Purchasing | G12: =COUNTIF(Data_05_Agu!E:E,F12) -> 38 | H12: =COUNTIF(Data_12_Agu!E:E,F12) -> 40
A13: ON_PROCESS | B13: =COUNTIF(Data_05_Agu!F:F,A13) -> 11 | C13: =COUNTIF(Data_12_Agu!F:F,A13) -> 13 | F13: Pengadaan Langsung | G13: =COUNTIF(Data_05_Agu!E:E,F13) -> 111 | H13: =COUNTIF(Data_12_Agu!E:E,F13) -> 115
A14: COMPLETED | B14: =COUNTIF(Data_05_Agu!F:F,A14) -> 17 | C14: =COUNTIF(Data_12_Agu!F:F,A14) -> 7 | F14: Dikecualikan | G14: =COUNTIF(Data_05_Agu!E:E,F14) -> 0 | H14: =COUNTIF(Data_12_Agu!E:E,F14) -> 1
A15: PAYMENT_OUTSIDE_SYSTEM | B15: =COUNTIF(Data_05_Agu!F:F,A15) -> 3 | C15: =COUNTIF(Data_12_Agu!F:F,A15) -> 3
A18: Transisi Status Menonjol | B18: Jumlah | C18: Catatan | F18: Catatan Analitis
A19: COMPLETED → BELUM REALISASI | B19: =COUNTIFS(Perbandingan!G:G,"COMPLETED",Perbandingan!H:H,"BELUM REALISASI") -> 10 | C19: Perlu ditelusuri karena dapat menyebabkan penurunan nilai realisasi pada snapshot terbaru. | F19: Penurunan total realisasi terutama perlu ditelusuri pada paket yang berubah dari COMPLETED menjadi BELUM REALISASI. Gunakan sheet Perubahan untuk melihat Kode RUP dan nilai sebelum/sesudah.
A20: BELUM REALISASI → ON_PROCESS | B20: =COUNTIFS(Perbandingan!G:G,"BELUM REALISASI",Perbandingan!H:H,"ON_PROCESS") -> 2 | C20: Menunjukkan paket yang mulai memiliki proses/realisasi pada snapshot terbaru.

Sheet Perbandingan
A1: Perbandingan Data Pengadaan BBPVP Bandung | 5 vs 12 Agustus 2026
A2: Kunci pencocokan: Kode RUP. Kategori 'tidak muncul' berarti kode tersebut ada pada data 5 Agustus tetapi tidak terdapat pada data 12 Agustus.
A4: Kode RUP | B4: Kategori Perubahan | C4: Field Berubah | D4: Nama Paket | E4: Metode 05 Agu | F4: Metode 12 Agu | G4: Status 05 Agu | H4: Status 12 Agu | I4: Pagu 05 Agu (Rp) | J4: Pagu 12 Agu (Rp) | K4: Δ Pagu (Rp) | L4: Realisasi 05 Agu (Rp) | M4: Realisasi 12 Agu (Rp) | N4: Δ Realisasi (Rp) | O4: Realisasi 05 Agu (%) | P4: Realisasi 12 Agu (%) | Q4: Δ Realisasi (pp)
A5: 62511623 | B5: TETAP | C5: - | D5: Belanja Peralatan dan Mesin Ekstrakomptabel | E5: Pengadaan Langsung | F5: Pengadaan Langsung | G5: BELUM REALISASI | H5: BELUM REALISASI | I5: 45000000 | J5: 45000000 | K5: =IF(OR(I5="",J5=""),"",J5-I5) -> 0 | L5: 0 | M5: 0 | N5: =IF(OR(L5="",M5=""),"",M5-L5) -> 0 | O5: 0 | P5: 0 | Q5: =IF(OR(O5="",P5=""),"",P5-O5) -> 0
A6: 62511624 | B6: TETAP | C6: - | D6: Belanja Jasa Langganan Internet | E6: E-Purchasing | F6: E-Purchasing | G6: ON_PROCESS | H6: ON_PROCESS | I6: 300000000 | J6: 300000000 | K6: =IF(OR(I6="",J6=""),"",J6-I6) -> 0 | L6: 299999700 | M6: 299999700 | N6: =IF(OR(L6="",M6=""),"",M6-L6) -> 0 | O6: 100 | P6: 100 | Q6: =IF(OR(O6="",P6=""),"",P6-O6) -> 0
A7: 62511627 | B7: TETAP | C7: - | D7: Belanja Langganan Telepon | E7: Pengadaan Langsung | F7: Pengadaan Langsung | G7: BELUM REALISASI | H7: BELUM REALISASI | I7: 66000000 | J7: 66000000 | K7: =IF(OR(I7="",J7=""),"",J7-I7) -> 0 | L7: 0 | M7: 0 | N7: =IF(OR(L7="",M7=""),"",M7-L7) -> 0 | O7: 0 | P7: 0 | Q7: =IF(OR(O7="",P7=""),"",P7-O7) -> 0
A8: 62511628 | B8: TETAP | C8: - | D8: Belanja Pemeliharaan Kendaraan | E8: Pengadaan Langsung | F8: Pengadaan Langsung | G8: BELUM REALISASI | H8: BELUM REALISASI | I8: 147600000 | J8: 147600000 | K8: =IF(OR(I8="",J8=""),"",J8-I8) -> 0 | L8: 0 | M8: 0 | N8: =IF(OR(L8="",M8=""),"",M8-L8) -> 0 | O8: 0 | P8: 0 | Q8: =IF(OR(O8="",P8=""),"",P8-O8) -> 0
A9: 62511633 | B9: BERUBAH | C9: Metode | D9: Belanja Langganan Listrik | E9: Pengadaan Langsung | F9: Dikecualikan | G9: BELUM REALISASI | H9: BELUM REALISASI | I9: 480000000 | J9: 480000000 | K9: =IF(OR(I9="",J9=""),"",J9-I9) -> 0 | L9: 0 | M9: 0 | N9: =IF(OR(L9="",M9=""),"",M9-L9) -> 0 | O9: 0 | P9: 0 | Q9: =IF(OR(O9="",P9=""),"",P9-O9) -> 0
A10: 62511634 | B10: TETAP | C10: - | D10: Belanja Pemeliharaan Jaringan | E10: Pengadaan Langsung | F10: Pengadaan Langsung | G10: COMPLETED | H10: COMPLETED | I10: 90000000 | J10: 90000000 | K10: =IF(OR(I10="",J10=""),"",J10-I10) -> 0 | L10: 68971100 | M10: 68971100 | N10: =IF(OR(L10="",M10=""),"",M10-L10) -> 0 | O10: 77 | P10: 77 | Q10: =IF(OR(O10="",P10=""),"",P10-O10) -> 0
A11: 62796402 | B11: TETAP | C11: - | D11: Jasa Outsourching Security | E11: E-Purchasing | F11: E-Purchasing | G11: ON_PROCESS | H11: ON_PROCESS | I11: 743952000 | J11: 743952000 | K11: =IF(OR(I11="",J11=""),"",J11-I11) -> 0 | L11: 743882568 | M11: 743882568 | N11: =IF(OR(L11="",M11=""),"",M11-L11) -> 0 | O11: 100 | P11: 100 | Q11: =IF(OR(O11="",P11=""),"",P11-O11) -> 0
A12: 63628978 | B12: TETAP | C12: - | D12: Modul Kerjasama | E12: Pengadaan Langsung | F12: Pengadaan Langsung | G12: BELUM REALISASI | H12: BELUM REALISASI | I12: 3200000 | J12: 3200000 | K12: =IF(OR(I12="",J12=""),"",J12-I12) -> 0 | L12: 0 | M12: 0 | N12: =IF(OR(L12="",M12=""),"",M12-L12) -> 0 | O12: 0 | P12: 0 | Q12: =IF(OR(O12="",P12=""),"",P12-O12) -> 0
A13: 63628981 | B13: TETAP | C13: - | D13: Bahan Pelatihan Penugasan/ Kerjasama | E13: Pengadaan Langsung | F13: Pengadaan Langsung | G13: BELUM REALISASI | H13: BELUM REALISASI | I13: 52200000 | J13: 52200000 | K13: =IF(OR(I13="",J13=""),"",J13-I13) -> 0 | L13: 0 | M13: 0 | N13: =IF(OR(L13="",M13=""),"",M13-L13) -> 0 | O13: 0 | P13: 0 | Q13: =IF(OR(O13="",P13=""),"",P13-O13) -> 0
A14: 63628982 | B14: TETAP | C14: - | D14: Pakaian Kerja Kerjasama | E14: E-Purchasing | F14: E-Purchasing | G14: BELUM REALISASI | H14: BELUM REALISASI | I14: 4800000 | J14: 4800000 | K14: =IF(OR(I14="",J14=""),"",J14-I14) -> 0 | L14: 0 | M14: 0 | N14: =IF(OR(L14="",M14=""),"",M14-L14) -> 0 | O14: 0 | P14: 0 | Q14: =IF(OR(O14="",P14=""),"",P14-O14) -> 0
A15: 63628984 | B15: TETAP | C15: - | D15: Belanja Konsumsi Peserta Pelatihan Penugasan/ Kerjasama (Hinode | E15: E-Purchasing | F15: E-Purchasing | G15: ON_PROCESS | H15: ON_PROCESS | I15: 253440000 | J15: 253440000 | K15: =IF(OR(I15="",J15=""),"",J15-I15) -> 0 | L15: 247104000 | M15: 247104000 | N15: =IF(OR(L15="",M15=""),"",M15-L15) -> 0 | O15: 98 | P15: 98 | Q15: =IF(OR(O15="",P15=""),"",P15-O15) -> 0
A16: 63628985 | B16: TETAP | C16: - | D16: Dokumentasi dan Pelaporan Kerjasama (Hinode) | E16: Pengadaan Langsung | F16: Pengadaan Langsung | G16: BELUM REALISASI | H16: BELUM REALISASI | I16: 750000 | J16: 750000 | K16: =IF(OR(I16="",J16=""),"",J16-I16) -> 0 | L16: 0 | M16: 0 | N16: =IF(OR(L16="",M16=""),"",M16-L16) -> 0 | O16: 0 | P16: 0 | Q16: =IF(OR(O16="",P16=""),"",P16-O16) -> 0
... A26: 63629897 | B26: TETAP | C26: - | D26: Safety Shoes Project Based Learning | E26: E-Purchasing | F26: E-Purchasing | G26: BELUM REALISASI | H26: BELUM REALISASI | I26: 168000000 | J26: 168000000 | K26: =IF(OR(I26="",J26=""),"",J26-I26) -> 0 | L26: 0 | M26: 0 | N26: =IF(OR(L26="",M26=""),"",M26-L26) -> 0 | O26: 0 | P26: 0 | Q26: =IF(OR(O26="",P26=""),"",P26-O26) -> 0
A27: 63629900 | B27: TIDAK MUNCUL DI 12 Agu | C27: Seluruh data (tidak muncul) | D27: Bahan Pelatihan Smart Tourism | E27: Pengadaan Langsung | G27: BELUM REALISASI | I27: 31544000 | K27: =IF(OR(I27="",J27=""),"",J27-I27) | L27: 0 | N27: =IF(OR(L27="",M27=""),"",M27-L27) | O27: 0 | Q27: =IF(OR(O27="",P27=""),"",P27-O27)
A28: 63629901 | B28: BERUBAH | C28: Nama Paket, Pagu (Rp) | D28: Bahan Project Based Learning Batch 2 (RM) | E28: Pengadaan Langsung | F28: Pengadaan Langsung | G28: BELUM REALISASI | H28: BELUM REALISASI | I28: 189000000 | J28: 184500000 | K28: =IF(OR(I28="",J28=""),"",J28-I28) -> -4500000 | L28: 0 | M28: 0 | N28: =IF(OR(L28="",M28=""),"",M28-L28) -> 0 | O28: 0 | P28: 0 | Q28: =IF(OR(O28="",P28=""),"",P28-O28) -> 0
A29: 63629902 | B29: BERUBAH | C29: Pagu (Rp) | D29: Dokumentasi dan Pelaporan Project Based Learning | E29: Pengadaan Langsung | F29: Pengadaan Langsung | G29: BELUM REALISASI | H29: BELUM REALISASI | I29: 6875000 | J29: 5250000 | K29: =IF(OR(I29="",J29=""),"",J29-I29) -> -1625000 | L29: 0 | M29: 0 | N29: =IF(OR(L29="",M29=""),"",M29-L29) -> 0 | O29: 0 | P29: 0 | Q29: =IF(OR(O29="",P29=""),"",P29-O29) -> 0
A30: 63629903 | B30: TETAP | C30: - | D30: Sertifikat Pelatihan | E30: Pengadaan Langsung | F30: Pengadaan Langsung | G30: BELUM REALISASI | H30: BELUM REALISASI | I30: 4800000 | J30: 4800000 | K30: =IF(OR(I30="",J30=""),"",J30-I30) -> 0 | L30: 0 | M30: 0 | N30: =IF(OR(L30="",M30=""),"",M30-L30) -> 0 | O30: 0 | P30: 0 | Q30: =IF(OR(O30="",P30=""),"",P30-O30) -> 0
A31: 63629907 | B31: BERUBAH | C31: Pagu (Rp) | D31: Paket Data | E31: Pengadaan Langsung | F31: Pengadaan Langsung | G31: BELUM REALISASI | H31: BELUM REALISASI | I31: 44000000 | J31: 29600000 | K31: =IF(OR(I31="",J31=""),"",J31-I31) -> -14400000 | L31: 0 | M31: 0 | N31: =IF(OR(L31="",M31=""),"",M31-L31) -> 0 | O31: 0 | P31: 0 | Q31: =IF(OR(O31="",P31=""),"",P31-O31) -> 0
A32: 63629912 | B32: BERUBAH | C32: Nama Paket, Pagu (Rp) | D32: Bahan Pelatihan Project Based Learning Batch 3 (PNBP) | E32: Pengadaan Langsung | F32: Pengadaan Langsung | G32: BELUM REALISASI | H32: BELUM REALISASI | I32: 46000000 | J32: 120000000 | K32: =IF(OR(I32="",J32=""),"",J32-I32) -> 74000000 | L32: 0 | M32: 0 | N32: =IF(OR(L32="",M32=""),"",M32-L32) -> 0 | O32: 0 | P32: 0 | Q32: =IF(OR(O32="",P32=""),"",P32-O32) -> 0
A33: 63632737 | B33: TETAP | C33: - | D33: Modul | E33: Pengadaan Langsung | F33: Pengadaan Langsung | G33: BELUM REALISASI | H33: BELUM REALISASI | I33: 49600000 | J33: 49600000 | K33: =IF(OR(I33="",J33=""),"",J33-I33) -> 0 | L33: 0 | M33: 0 | N33: =IF(OR(L33="",M33=""),"",M33-L33) -> 0 | O33: 0 | P33: 0 | Q33: =IF(OR(O33="",P33=""),"",P33-O33) -> 0
A34: 63632739 | B34: TETAP | C34: - | D34: Bahan Pelatihan Operator Forklift (280 JP) | E34: Pengadaan Langsung | F34: Pengadaan Langsung | G34: BELUM REALISASI | H34: BELUM REALISASI | I34: 140000000 | J34: 140000000 | K34: =IF(OR(I34="",J34=""),"",J34-I34) -> 0 | L34: 0 | M34: 0 | N34: =IF(OR(L34="",M34=""),"",M34-L34) -> 0 | O34: 0 | P34: 0 | Q34: =IF(OR(O34="",P34=""),"",P34-O34) -> 0
A35: 63632741 | B35: TETAP | C35: - | D35: Dokumentasi dan Pelaporan | E35: Pengadaan Langsung | F35: Pengadaan Langsung | G35: BELUM REALISASI | H35: BELUM REALISASI | I35: 7750000 | J35: 7750000 | K35: =IF(OR(I35="",J35=""),"",J35-I35) -> 0 | L35: 0 | M35: 0 | N35: =IF(OR(L35="",M35=""),"",M35-L35) -> 0 | O35: 0 | P35: 0 | Q35: =IF(OR(O35="",P35=""),"",P35-O35) -> 0
A36: 63632742 | B36: TETAP | C36: - | D36: Bahan Pelatihan Penggambaran Model 3D dengan CAD (260 JP) | E36: Pengadaan Langsung | F36: Pengadaan Langsung | G36: BELUM REALISASI | H36: BELUM REALISASI | I36: 30000000 | J36: 30000000 | K36: =IF(OR(I36="",J36=""),"",J36-I36) -> 0 | L36: 0 | M36: 0 | N36: =IF(OR(L36="",M36=""),"",M36-L36) -> 0 | O36: 0 | P36: 0 | Q36: =IF(OR(O36="",P36=""),"",P36-O36) -> 0
A37: 63632743 | B37: TETAP | C37: - | D37: Bahan Pelatihan Peracikan Minuman Kopi 180 JP | E37: Pengadaan Langsung | F37: Pengadaan Langsung | G37: BELUM REALISASI | H37: BELUM REALISASI | I37: 29500000 | J37: 29500000 | K37: =IF(OR(I37="",J37=""),"",J37-I37) -> 0 | L37: 0 | M37: 0 | N37: =IF(OR(L37="",M37=""),"",M37-L37) -> 0 | O37: 0 | P37: 0 | Q37: =IF(OR(O37="",P37=""),"",P37-O37) -> 0
A38: 63632744 | B38: TETAP | C38: - | D38: Sertifikat Pelatihan | E38: Pengadaan Langsung | F38: Pengadaan Langsung | G38: BELUM REALISASI | H38: BELUM REALISASI | I38: 4960000 | J38: 4960000 | K38: =IF(OR(I38="",J38=""),"",J38-I38) -> 0 | L38: 0 | M38: 0 | N38: =IF(OR(L38="",M38=""),"",M38-L38) -> 0 | O38: 0 | P38: 0 | Q38: =IF(OR(O38="",P38=""),"",P38-O38) -> 0
A39: 63632749 | B39: TETAP | C39: - | D39: Bahan Pelatihan | E39: Pengadaan Langsung | F39: Pengadaan Langsung | G39: BELUM REALISASI | H39: BELUM REALISASI | I39: 40000000 | J39: 40000000 | K39: =IF(OR(I39="",J39=""),"",J39-I39) -> 0 | L39: 0 | M39: 0 | N39: =IF(OR(L39="",M39=""),"",M39-L39) -> 0 | O39: 0 | P39: 0 | Q39: =IF(OR(O39="",P39=""),"",P39-O39) -> 0
... A131: 66619908 | B131: TETAP | C131: - | D131: Bahan Pelatihan PBK Reguler Batch 1 Kejuruan Otomotive (Service Sepeda Motor Sistem Injeksi, Tune Up Sepeda Motor Konvensional, Pemeliharaan Kendaraan Ringan Sistem Konvensional) | E131: Pengadaan Langsung | F131: Pengadaan Langsung | G131: BELUM REALISASI | H131: BELUM REALISASI | I131: 129600000 | J131: 129600000 | K131: =IF(OR(I131="",J131=""),"",J131-I131) -> 0 | L131: 0 | M131: 0 | N131: =IF(OR(L131="",M131=""),"",M131-L131) -> 0 | O131: 0 | P131: 0 | Q131: =IF(OR(O131="",P131=""),"",P131-O131) -> 0
A132: 66638139 | B132: TIDAK MUNCUL DI 12 Agu | C132: Seluruh data (tidak muncul) | D132: Bahan Pelatihan Smart Manufacturing | E132: Pengadaan Langsung | G132: BELUM REALISASI | I132: 193484000 | K132: =IF(OR(I132="",J132=""),"",J132-I132) | L132: 0 | N132: =IF(OR(L132="",M132=""),"",M132-L132) | O132: 0 | Q132: =IF(OR(O132="",P132=""),"",P132-O132)
A133: 66812985 | B133: BERUBAH | C133: Status, Realisasi (Rp), Realisasi (%) | D133: Bahan Pelatihan Batch 1 (Operator Forklift, Pemeliharaan Berkala Kendaraan Ringan Sistem Injeksi, Penggambaran Model 3D dengan CAD, Teknisi AC Residential, Teknisi Perawatan AC Residential) | E133: Pengadaan Langsung | F133: Pengadaan Langsung | G133: COMPLETED | H133: BELUM REALISASI | I133: 176040000 | J133: 176040000 | K133: =IF(OR(I133="",J133=""),"",J133-I133) -> 0 | L133: 1.1242279e+08 | M133: 0 | N133: =IF(OR(L133="",M133=""),"",M133-L133) -> -1.1242279e+08 | O133: 64 | P133: 0 | Q133: =IF(OR(O133="",P133=""),"",P133-O133) -> -64
A134: 66813076 | B134: TETAP | C134: - | D134: Bahan Pelatihan Penggambaran Model 3D dengan CAD | E134: Pengadaan Langsung | F134: Pengadaan Langsung | G134: BELUM REALISASI | H134: BELUM REALISASI | I134: 15000000 | J134: 15000000 | K134: =IF(OR(I134="",J134=""),"",J134-I134) -> 0 | L134: 0 | M134: 0 | N134: =IF(OR(L134="",M134=""),"",M134-L134) -> 0 | O134: 0 | P134: 0 | Q134: =IF(OR(O134="",P134=""),"",P134-O134) -> 0
A135: 66813325 | B135: BERUBAH | C135: Status, Realisasi (Rp), Realisasi (%) | D135: Bahan Pelatihan Project Based Learning Batch 1 (Smart Creative IT Skill dan Smart Building) | E135: Pengadaan Langsung | F135: Pengadaan Langsung | G135: COMPLETED | H135: BELUM REALISASI | I135: 125000000 | J135: 125000000 | K135: =IF(OR(I135="",J135=""),"",J135-I135) -> 0 | L135: 58581425 | M135: 0 | N135: =IF(OR(L135="",M135=""),"",M135-L135) -> -58581425 | O135: 47 | P135: 0 | Q135: =IF(OR(O135="",P135=""),"",P135-O135) -> -47
A136: 66813389 | B136: BERUBAH | C136: Nama Paket, Pagu (Rp) | D136: Bahan Pelatihan Project Based Learning Batch 3 (RM) | E136: Pengadaan Langsung | F136: Pengadaan Langsung | G136: BELUM REALISASI | H136: BELUM REALISASI | I136: 158732000 | J136: 173000000 | K136: =IF(OR(I136="",J136=""),"",J136-I136) -> 14268000 | L136: 0 | M136: 0 | N136: =IF(OR(L136="",M136=""),"",M136-L136) -> 0 | O136: 0 | P136: 0 | Q136: =IF(OR(O136="",P136=""),"",P136-O136) -> 0
A137: 66814932 | B137: TETAP | C137: - | D137: Belanja Bahan UPTD BLK Kota Banjar | E137: Pengadaan Langsung | F137: Pengadaan Langsung | G137: BELUM REALISASI | H137: BELUM REALISASI | I137: 151470000 | J137: 151470000 | K137: =IF(OR(I137="",J137=""),"",J137-I137) -> 0 | L137: 0 | M137: 0 | N137: =IF(OR(L137="",M137=""),"",M137-L137) -> 0 | O137: 0 | P137: 0 | Q137: =IF(OR(O137="",P137=""),"",P137-O137) -> 0
A138: 66815105 | B138: BERUBAH | C138: Status, Realisasi (Rp), Realisasi (%) | D138: Pengadaan Bahan Pelatihan Berbasis Kompetensi BBPVP Bandung di UPT Sumedang dan BLK Purwakarta | E138: Pengadaan Langsung | F138: Pengadaan Langsung | G138: COMPLETED | H138: BELUM REALISASI | I138: 120950000 | J138: 120950000 | K138: =IF(OR(I138="",J138=""),"",J138-I138) -> 0 | L138: 92935094 | M138: 0 | N138: =IF(OR(L138="",M138=""),"",M138-L138) -> -92935094 | O138: 77 | P138: 0 | Q138: =IF(OR(O138="",P138=""),"",P138-O138) -> -77
A139: 66815271 | B139: BERUBAH | C139: Status, Realisasi (Rp), Realisasi (%) | D139: Pengadaan Bahan Pelatihan Berbasis Kompetensi BBPVP Bandung di UPT BLK Garut | E139: Pengadaan Langsung | F139: Pengadaan Langsung | G139: COMPLETED | H139: BELUM REALISASI | I139: 197046000 | J139: 197046000 | K139: =IF(OR(I139="",J139=""),"",J139-I139) -> 0 | L139: 165834111 | M139: 0 | N139: =IF(OR(L139="",M139=""),"",M139-L139) -> -165834111 | O139: 84 | P139: 0 | Q139: =IF(OR(O139="",P139=""),"",P139-O139) -> -84
A140: 66815289 | B140: TETAP | C140: - | D140: Pengadaan Bahan Pelatihan Berbasis Kompetensi BBPVP Bandung di UPTD BLK Kab. Tasikmalaya dan UPT BLK Garut | E140: Pengadaan Langsung | F140: Pengadaan Langsung | G140: BELUM REALISASI | H140: BELUM REALISASI | I140: 179046000 | J140: 179046000 | K140: =IF(OR(I140="",J140=""),"",J140-I140) -> 0 | L140: 0 | M140: 0 | N140: =IF(OR(L140="",M140=""),"",M140-L140) -> 0 | O140: 0 | P140: 0 | Q140: =IF(OR(O140="",P140=""),"",P140-O140) -> 0
A141: 66894598 | B141: BERUBAH | C141: Status, Realisasi (Rp), Realisasi (%) | D141: Pengadaan Bahan Pelatihan Berbasis Kompetensi BBPVP Bandung di UPTD BLK Kab. Kuningan, UPTD KLK Ciamis dan UPTD BLK Kota Banjar | E141: Pengadaan Langsung | F141: Pengadaan Langsung | G141: COMPLETED | H141: BELUM REALISASI | I141: 159046000 | J141: 159046000 | K141: =IF(OR(I141="",J141=""),"",J141-I141) -> 0 | L141: 1.3405866e+08 | M141: 0 | N141: =IF(OR(L141="",M141=""),"",M141-L141) -> -1.3405866e+08 | O141: 84 | P141: 0 | Q141: =IF(OR(O141="",P141=""),"",P141-O141) -> -84
...

Sheet Perubahan
A1: Daftar Paket yang Berubah / Baru / Tidak Muncul
A2: Sheet ini merupakan filter dari Perbandingan untuk memudahkan penelusuran perubahan antara 5 dan 12 Agustus 2026.
A4: Kode RUP | B4: Kategori Perubahan | C4: Field Berubah | D4: Nama Paket | E4: Metode 05 Agu | F4: Metode 12 Agu | G4: Status 05 Agu | H4: Status 12 Agu | I4: Pagu 05 Agu (Rp) | J4: Pagu 12 Agu (Rp) | K4: Δ Pagu (Rp) | L4: Realisasi 05 Agu (Rp) | M4: Realisasi 12 Agu (Rp) | N4: Δ Realisasi (Rp) | O4: Realisasi 05 Agu (%) | P4: Realisasi 12 Agu (%) | Q4: Δ Realisasi (pp)
A5: 67630586 | B5: BARU DI 12 Agu | C5: Seluruh data (paket baru) | D5: Operasional Pelaksanaan Sertifikasi Lulusan Pelatihan | F5: Pengadaan Langsung | H5: BELUM REALISASI | J5: 59259000 | K5: =IF(OR(I5="",J5=""),"",J5-I5) | M5: 0 | N5: =IF(OR(L5="",M5=""),"",M5-L5) | P5: 0 | Q5: =IF(OR(O5="",P5=""),"",P5-O5)
A6: 67630616 | B6: BARU DI 12 Agu | C6: Seluruh data (paket baru) | D6: Pelaksanaan Refresment Pengembangan Skema dan Perangkat Sertifikasi | F6: Pengadaan Langsung | H6: BELUM REALISASI | J6: 37475000 | K6: =IF(OR(I6="",J6=""),"",J6-I6) | M6: 0 | N6: =IF(OR(L6="",M6=""),"",M6-L6) | P6: 0 | Q6: =IF(OR(O6="",P6=""),"",P6-O6)
A7: 67634310 | B7: BARU DI 12 Agu | C7: Seluruh data (paket baru) | D7: Pengadaan Bahan PBK Tahap 2 UPTD BLK Kab Sukabumi Kejuruan Manufaktur | F7: Pengadaan Langsung | H7: BELUM REALISASI | J7: 97500000 | K7: =IF(OR(I7="",J7=""),"",J7-I7) | M7: 0 | N7: =IF(OR(L7="",M7=""),"",M7-L7) | P7: 0 | Q7: =IF(OR(O7="",P7=""),"",P7-O7)
A8: 67634319 | B8: BARU DI 12 Agu | C8: Seluruh data (paket baru) | D8: Bahan Pelatihan UPTD BLK Sukabumi | F8: Pengadaan Langsung | H8: BELUM REALISASI | J8: 10410000 | K8: =IF(OR(I8="",J8=""),"",J8-I8) | M8: 0 | N8: =IF(OR(L8="",M8=""),"",M8-L8) | P8: 0 | Q8: =IF(OR(O8="",P8=""),"",P8-O8)
A9: 67635261 | B9: BARU DI 12 Agu | C9: Seluruh data (paket baru) | D9: Belanja Sewa Pendukung Operasional Penyelenggaraan PBK di UPTP | F9: Pengadaan Langsung | H9: BELUM REALISASI | J9: 25800000 | K9: =IF(OR(I9="",J9=""),"",J9-I9) | M9: 0 | N9: =IF(OR(L9="",M9=""),"",M9-L9) | P9: 0 | Q9: =IF(OR(O9="",P9=""),"",P9-O9)
A10: 67635280 | B10: BARU DI 12 Agu | C10: Seluruh data (paket baru) | D10: Belanja Jasa Lainnya Operasional Penyelenggaraan PBK di UPTP | F10: Pengadaan Langsung | H10: BELUM REALISASI | J10: 28000000 | K10: =IF(OR(I10="",J10=""),"",J10-I10) | M10: 0 | N10: =IF(OR(L10="",M10=""),"",M10-L10) | P10: 0 | Q10: =IF(OR(O10="",P10=""),"",P10-O10)
A11: 67635295 | B11: BARU DI 12 Agu | C11: Seluruh data (paket baru) | D11: Belanja Bahan Talent Inovation Hub | F11: Pengadaan Langsung | H11: BELUM REALISASI | J11: 15200000 | K11: =IF(OR(I11="",J11=""),"",J11-I11) | M11: 0 | N11: =IF(OR(L11="",M11=""),"",M11-L11) | P11: 0 | Q11: =IF(OR(O11="",P11=""),"",P11-O11)
A12: 67635323 | B12: BARU DI 12 Agu | C12: Seluruh data (paket baru) | D12: Belanja Pengiriman Surat Dinas Pos Pusat | F12: Pengadaan Langsung | H12: BELUM REALISASI | J12: 2000000 | K12: =IF(OR(I12="",J12=""),"",J12-I12) | M12: 0 | N12: =IF(OR(L12="",M12=""),"",M12-L12) | P12: 0 | Q12: =IF(OR(O12="",P12=""),"",P12-O12)
A13: 67635355 | B13: BARU DI 12 Agu | C13: Seluruh data (paket baru) | D13: Operasional Penyelenggaraan Pelatihan Lainnya (Sewa Peralatan Pelatihan) | F13: Pengadaan Langsung | H13: BELUM REALISASI | J13: 64546000 | K13: =IF(OR(I13="",J13=""),"",J13-I13) | M13: 0 | N13: =IF(OR(L13="",M13=""),"",M13-L13) | P13: 0 | Q13: =IF(OR(O13="",P13=""),"",P13-O13)
A14: 63629900 | B14: TIDAK MUNCUL DI 12 Agu | C14: Seluruh data (tidak muncul) | D14: Bahan Pelatihan Smart Tourism | E14: Pengadaan Langsung | G14: BELUM REALISASI | I14: 31544000 | K14: =IF(OR(I14="",J14=""),"",J14-I14) | L14: 0 | N14: =IF(OR(L14="",M14=""),"",M14-L14) | O14: 0 | Q14: =IF(OR(O14="",P14=""),"",P14-O14)
A15: 66638139 | B15: TIDAK MUNCUL DI 12 Agu | C15: Seluruh data (tidak muncul) | D15: Bahan Pelatihan Smart Manufacturing | E15: Pengadaan Langsung | G15: BELUM REALISASI | I15: 193484000 | K15: =IF(OR(I15="",J15=""),"",J15-I15) | L15: 0 | N15: =IF(OR(L15="",M15=""),"",M15-L15) | O15: 0 | Q15: =IF(OR(O15="",P15=""),"",P15-O15)
A16: 62511633 | B16: BERUBAH | C16: Metode | D16: Belanja Langganan Listrik | E16: Pengadaan Langsung | F16: Dikecualikan | G16: BELUM REALISASI | H16: BELUM REALISASI | I16: 480000000 | J16: 480000000 | K16: =IF(OR(I16="",J16=""),"",J16-I16) -> 0 | L16: 0 | M16: 0 | N16: =IF(OR(L16="",M16=""),"",M16-L16) -> 0 | O16: 0 | P16: 0 | Q16: =IF(OR(O16="",P16=""),"",P16-O16) -> 0
A17: 63629681 | B17: BERUBAH | C17: Pagu (Rp) | D17: Bahan Pelatihan Tailor Made Training (RM) | E17: Pengadaan Langsung | F17: Pengadaan Langsung | G17: BELUM REALISASI | H17: BELUM REALISASI | I17: 150000000 | J17: 75000000 | K17: =IF(OR(I17="",J17=""),"",J17-I17) -> -75000000 | L17: 0 | M17: 0 | N17: =IF(OR(L17="",M17=""),"",M17-L17) -> 0 | O17: 0 | P17: 0 | Q17: =IF(OR(O17="",P17=""),"",P17-O17) -> 0
A18: 63629682 | B18: BERUBAH | C18: Pagu (Rp) | D18: Dokumentasi dan Pelaporan Tailor Made Training (PNBP) | E18: Pengadaan Langsung | F18: Pengadaan Langsung | G18: BELUM REALISASI | H18: BELUM REALISASI | I18: 4125000 | J18: 8250000 | K18: =IF(OR(I18="",J18=""),"",J18-I18) -> 4125000 | L18: 0 | M18: 0 | N18: =IF(OR(L18="",M18=""),"",M18-L18) -> 0 | O18: 0 | P18: 0 | Q18: =IF(OR(O18="",P18=""),"",P18-O18) -> 0
A19: 63629683 | B19: BERUBAH | C19: Pagu (Rp), Realisasi (%), Status Kurasi AI, Catatan Kurasi AI, Rekomendasi Kurasi AI | D19: Bahan Pelatihan Tailor Made Training (PNBP) | E19: Pengadaan Langsung | F19: Pengadaan Langsung | G19: COMPLETED | H19: COMPLETED | I19: 330000000 | J19: 115500000 | K19: =IF(OR(I19="",J19=""),"",J19-I19) -> -214500000 | L19: 20982889 | M19: 20982889 | N19: =IF(OR(L19="",M19=""),"",M19-L19) -> 0 | O19: 6 | P19: 18 | Q19: =IF(OR(O19="",P19=""),"",P19-O19) -> 12
A20: 63629685 | B20: BERUBAH | C20: Nama Paket, Pagu (Rp) | D20: Konsumsi Peserta Pelatihan (RM) | E20: E-Purchasing | F20: E-Purchasing | G20: BELUM REALISASI | H20: BELUM REALISASI | I20: 96000000 | J20: 24000000 | K20: =IF(OR(I20="",J20=""),"",J20-I20) -> -72000000 | L20: 0 | M20: 0 | N20: =IF(OR(L20="",M20=""),"",M20-L20) -> 0 | O20: 0 | P20: 0 | Q20: =IF(OR(O20="",P20=""),"",P20-O20) -> 0
A21: 63629890 | B21: BERUBAH | C21: Pagu (Rp) | D21: Modul Project Based Learning | E21: Pengadaan Langsung | F21: Pengadaan Langsung | G21: BELUM REALISASI | H21: BELUM REALISASI | I21: 48000000 | J21: 33600000 | K21: =IF(OR(I21="",J21=""),"",J21-I21) -> -14400000 | L21: 0 | M21: 0 | N21: =IF(OR(L21="",M21=""),"",M21-L21) -> 0 | O21: 0 | P21: 0 | Q21: =IF(OR(O21="",P21=""),"",P21-O21) -> 0
A22: 63629891 | B22: BERUBAH | C22: Nama Paket | D22: Bahan Pelatihan Project Based Learning Batch 2 (PNBP) | E22: Pengadaan Langsung | F22: Pengadaan Langsung | G22: BELUM REALISASI | H22: BELUM REALISASI | I22: 44000000 | J22: 44000000 | K22: =IF(OR(I22="",J22=""),"",J22-I22) -> 0 | L22: 0 | M22: 0 | N22: =IF(OR(L22="",M22=""),"",M22-L22) -> 0 | O22: 0 | P22: 0 | Q22: =IF(OR(O22="",P22=""),"",P22-O22) -> 0
A23: 63629901 | B23: BERUBAH | C23: Nama Paket, Pagu (Rp) | D23: Bahan Project Based Learning Batch 2 (RM) | E23: Pengadaan Langsung | F23: Pengadaan Langsung | G23: BELUM REALISASI | H23: BELUM REALISASI | I23: 189000000 | J23: 184500000 | K23: =IF(OR(I23="",J23=""),"",J23-I23) -> -4500000 | L23: 0 | M23: 0 | N23: =IF(OR(L23="",M23=""),"",M23-L23) -> 0 | O23: 0 | P23: 0 | Q23: =IF(OR(O23="",P23=""),"",P23-O23) -> 0
A24: 63629902 | B24: BERUBAH | C24: Pagu (Rp) | D24: Dokumentasi dan Pelaporan Project Based Learning | E24: Pengadaan Langsung | F24: Pengadaan Langsung | G24: BELUM REALISASI | H24: BELUM REALISASI | I24: 6875000 | J24: 5250000 | K24: =IF(OR(I24="",J24=""),"",J24-I24) -> -1625000 | L24: 0 | M24: 0 | N24: =IF(OR(L24="",M24=""),"",M24-L24) -> 0 | O24: 0 | P24: 0 | Q24: =IF(OR(O24="",P24=""),"",P24-O24) -> 0
A25: 63629907 | B25: BERUBAH | C25: Pagu (Rp) | D25: Paket Data | E25: Pengadaan Langsung | F25: Pengadaan Langsung | G25: BELUM REALISASI | H25: BELUM REALISASI | I25: 44000000 | J25: 29600000 | K25: =IF(OR(I25="",J25=""),"",J25-I25) -> -14400000 | L25: 0 | M25: 0 | N25: =IF(OR(L25="",M25=""),"",M25-L25) -> 0 | O25: 0 | P25: 0 | Q25: =IF(OR(O25="",P25=""),"",P25-O25) -> 0
A26: 63629912 | B26: BERUBAH | C26: Nama Paket, Pagu (Rp) | D26: Bahan Pelatihan Project Based Learning Batch 3 (PNBP) | E26: Pengadaan Langsung | F26: Pengadaan Langsung | G26: BELUM REALISASI | H26: BELUM REALISASI | I26: 46000000 | J26: 120000000 | K26: =IF(OR(I26="",J26=""),"",J26-I26) -> 74000000 | L26: 0 | M26: 0 | N26: =IF(OR(L26="",M26=""),"",M26-L26) -> 0 | O26: 0 | P26: 0 | Q26: =IF(OR(O26="",P26=""),"",P26-O26) -> 0
A27: 63632905 | B27: BERUBAH | C27: Nama Paket, Pagu (Rp) | D27: Bahan Operasional Penyelenggaraan PBK di UPTD | E27: Pengadaan Langsung | F27: Pengadaan Langsung | G27: BELUM REALISASI | H27: BELUM REALISASI | I27: 7600000 | J27: 24500000 | K27: =IF(OR(I27="",J27=""),"",J27-I27) -> 16900000 | L27: 0 | M27: 0 | N27: =IF(OR(L27="",M27=""),"",M27-L27) -> 0 | O27: 0 | P27: 0 | Q27: =IF(OR(O27="",P27=""),"",P27-O27) -> 0
... A56: 67568320 | B56: BERUBAH | C56: Status Kurasi AI, Catatan Kurasi AI, Rekomendasi Kurasi AI | D56: Sewa Peralatan Pelatihan | E56: E-Purchasing | F56: E-Purchasing | G56: ON_PROCESS | H56: ON_PROCESS | I56: 100904000 | J56: 100904000 | K56: =IF(OR(I56="",J56=""),"",J56-I56) -> 0 | L56: 37296000 | M56: 37296000 | N56: =IF(OR(L56="",M56=""),"",M56-L56) -> 0 | O56: 37 | P56: 37 | Q56: =IF(OR(O56="",P56=""),"",P56-O56) -> 0

Sheet Data_05_Agu
A1: Laporan Ringkasan Pengadaan - BBPVP Bandung
A2: Tanggal data: 5 Agustus 2026
A3: Kode RUP | B3: Satuan Kerja | C3: Nama PPK | D3: Nama Paket | E3: Metode | F3: Status | G3: Pagu (Rp) | H3: Realisasi (Rp) | I3: Realisasi (%) | J3: Status Kurasi AI | K3: Catatan Kurasi AI | L3: Rekomendasi Kurasi AI
A4: 62511624 | B4: Balai Besar Pelatihan Vokasi dan Produktivitas Bandung | C4: Christiana Dewi Rasmawati | D4: Belanja Jasa Langganan Internet | E4: E-Purchasing | F4: ON_PROCESS | G4: 300000000 | H4: 299999700 | I4: 100 | J4: Akurat | K4: Metode E-Purchasing tidak dibatasi nilai pagu pengadaan. | L4: Dapat dilanjutkan.
A5: 62796402 | B5: Balai Besar Pelatihan Vokasi dan Produktivitas Bandung | C5: Christiana Dewi Rasmawati | D5: Jasa Outsourching Security | E5: E-Purchasing | F5: ON_PROCESS | G5: 743952000 | H5: 743882568 | I5: 100 | J5: Akurat | K5: Sesuai dengan aturan pengadaan. | L5: Dapat dilanjutkan ke tahap berikutnya.
A6: 63628982 | B6: Balai Besar Pelatihan Vokasi dan Produktivitas Bandung | C6: Christiana Dewi Rasmawati | D6: Pakaian Kerja Kerjasama | E6: E-Purchasing | F6: BELUM REALISASI | G6: 4800000 | H6: 0 | I6: 0 | J6: Akurat | K6: Sesuai dengan aturan batasan nilai dan metode pengadaan. | L6: Dapat dilanjutkan ke tahap berikutnya.
A7: 63628984 | B7: Balai Besar Pelatihan Vokasi dan Produktivitas Bandung | C7: Christiana Dewi Rasmawati | D7: Belanja Konsumsi Peserta Pelatihan Penugasan/ Kerjasama (Hinode | E7: E-Purchasing | F7: ON_PROCESS | G7: 253440000 | H7: 247104000 | I7: 98 | J7: Akurat | K7: Sesuai dengan aturan batasan nilai dan metode pengadaan. | L7: Dapat dilanjutkan ke tahap berikutnya.
A8: 63629685 | B8: Balai Besar Pelatihan Vokasi dan Produktivitas Bandung | C8: Christiana Dewi Rasmawati | D8: Konsumsi Peserta Pelatihan | E8: E-Purchasing | F8: BELUM REALISASI | G8: 96000000 | H8: 0 | I8: 0 | J8: Akurat | K8: Sesuai dengan aturan batasan nilai dan metode pengadaan. | L8: Dapat dilanjutkan ke tahap berikutnya.
A9: 63629686 | B9: Balai Besar Pelatihan Vokasi dan Produktivitas Bandung | C9: Christiana Dewi Rasmawati | D9: Konsumsi Peserta Pelatihan Tailor Made Training (PNBP) | E9: E-Purchasing | F9: BELUM REALISASI | G9: 105600000 | H9: 0 | I9: 0 | J9: Akurat | K9: Sesuai dengan aturan batasan nilai dan metode pengadaan. | L9: Dapat dilanjutkan ke tahap berikutnya.
A10: 63629896 | B10: Balai Besar Pelatihan Vokasi dan Produktivitas Bandung | C10: Christiana Dewi Rasmawati | D10: Pakaian Kerja Project Based Learning | E10: E-Purchasing | F10: PAYMENT_OUTSIDE_SYSTEM | G10: 72000000 | H10: 71757504 | I10: 100 | J10: Akurat | K10: Sesuai dengan aturan batasan nilai dan metode pengadaan. | L10: Dapat dilanjutkan ke tahap berikutnya.
A11: 63629897 | B11: Balai Besar Pelatihan Vokasi dan Produktivitas Bandung | C11: Christiana Dewi Rasmawati | D11: Safety Shoes Project Based Learning | E11: E-Purchasing | F11: BELUM REALISASI | G11: 168000000 | H11: 0 | I11: 0 | J11: Akurat | K11: Sesuai dengan aturan batasan nilai dan metode pengadaan. | L11: Dapat dilanjutkan ke tahap berikutnya.
A12: 63632766 | B12: Balai Besar Pelatihan Vokasi dan Produktivitas Bandung | C12: Christiana Dewi Rasmawati | D12: Safety Shoes PBK Reguler | E12: E-Purchasing | F12: COMPLETED | G12: 145600000 | H12: 39177600 | I12: 27 | J12: Akurat | K12: Sesuai dengan aturan batasan nilai dan metode pengadaan. | L12: Dapat dilanjutkan ke tahap berikutnya.
A13: 63632770 | B13: Balai Besar Pelatihan Vokasi dan Produktivitas Bandung | C13: Christiana Dewi Rasmawati | D13: Konsumsi Peserta Pelatihan Penugasan | E13: E-Purchasing | F13: BELUM REALISASI | G13: 38400000 | H13: 0 | I13: 0 | J13: Akurat | K13: Sesuai dengan aturan batasan nilai dan metode pengadaan. | L13: Dapat dilanjutkan ke tahap berikutnya.
A14: 63633231 | B14: Balai Besar Pelatihan Vokasi dan Produktivitas Bandung | C14: Christiana Dewi Rasmawati | D14: Konsumsi Peserta Pelatihan Vokasi yang Mendukung Pekerjaan Hijau (Green Jobs) | E14: E-Purchasing | F14: BELUM REALISASI | G14: 67200000 | H14: 0 | I14: 0 | J14: Akurat | K14: Metode pengadaan sesuai dengan batasan nilai pagu paket. | L14: Dapat dilanjutkan ke tahap pengadaan berikutnya.
A15: 63715796 | B15: Balai Besar Pelatihan Vokasi dan Produktivitas Bandung | C15: Christiana Dewi Rasmawati | D15: Belanja Bahan Tahap Perencanaan (Bimbingan Konsultasi) | E15: E-Purchasing | F15: BELUM REALISASI | G15: 3000000 | H15: 0 | I15: 0 | J15: Akurat | K15: Metode pengadaan sesuai dengan batasan nilai pagu paket. | L15: Dapat dilanjutkan ke tahap pengadaan berikutnya.
... A152: 67521824 | B152: Balai Besar Pelatihan Vokasi dan Produktivitas Bandung | C152: Christiana Dewi Rasmawati | D152: Pengadaan Modul Peserta PVN UPTD Binaan BBPVP Bandung | E152: Pengadaan Langsung | F152: BELUM REALISASI | G152: 28450000 | H152: 0 | I152: 0 | J152: Akurat | K152: Pagu Rp28.450.000 untuk pengadaan Barang menggunakan Pengadaan Langsung sudah sesuai (maksimal Rp200.000.000). | L152: Catatan: Pengadaan Langsung ini wajib menggunakan SPSE fitur transaksional sesuai Perpres 46/2025.

Sheet Data_12_Agu
A1: Laporan Ringkasan Pengadaan - BBPVP Bandung
A2: Tanggal data: 12 Agustus 2026
A3: Kode RUP | B3: Satuan Kerja | C3: Nama PPK | D3: Nama Paket | E3: Metode | F3: Status | G3: Pagu (Rp) | H3: Realisasi (Rp) | I3: Realisasi (%) | J3: Status Kurasi AI | K3: Catatan Kurasi AI | L3: Rekomendasi Kurasi AI
A4: 62511624 | B4: Balai Besar Pelatihan Vokasi dan Produktivitas Bandung | C4: Christiana Dewi Rasmawati | D4: Belanja Jasa Langganan Internet | E4: E-Purchasing | F4: ON_PROCESS | G4: 300000000 | H4: 299999700 | I4: 100 | J4: Akurat | K4: Metode E-Purchasing tidak dibatasi nilai pagu pengadaan. | L4: Dapat dilanjutkan.
A5: 62796402 | B5: Balai Besar Pelatihan Vokasi dan Produktivitas Bandung | C5: Christiana Dewi Rasmawati | D5: Jasa Outsourching Security | E5: E-Purchasing | F5: ON_PROCESS | G5: 743952000 | H5: 743882568 | I5: 100 | J5: Akurat | K5: Sesuai dengan aturan pengadaan. | L5: Dapat dilanjutkan ke tahap berikutnya.
A6: 63628982 | B6: Balai Besar Pelatihan Vokasi dan Produktivitas Bandung | C6: Christiana Dewi Rasmawati | D6: Pakaian Kerja Kerjasama | E6: E-Purchasing | F6: BELUM REALISASI | G6: 4800000 | H6: 0 | I6: 0 | J6: Akurat | K6: Sesuai dengan aturan batasan nilai dan metode pengadaan. | L6: Dapat dilanjutkan ke tahap berikutnya.
A7: 63628984 | B7: Balai Besar Pelatihan Vokasi dan Produktivitas Bandung | C7: Christiana Dewi Rasmawati | D7: Belanja Konsumsi Peserta Pelatihan Penugasan/ Kerjasama (Hinode | E7: E-Purchasing | F7: ON_PROCESS | G7: 253440000 | H7: 247104000 | I7: 98 | J7: Akurat | K7: Sesuai dengan aturan batasan nilai dan metode pengadaan. | L7: Dapat dilanjutkan ke tahap berikutnya.
A8: 63629685 | B8: Balai Besar Pelatihan Vokasi dan Produktivitas Bandung | C8: Christiana Dewi Rasmawati | D8: Konsumsi Peserta Pelatihan (RM) | E8: E-Purchasing | F8: BELUM REALISASI | G8: 24000000 | H8: 0 | I8: 0 | J8: Akurat | K8: Sesuai dengan aturan batasan nilai dan metode pengadaan. | L8: Dapat dilanjutkan ke tahap berikutnya.
A9: 63629686 | B9: Balai Besar Pelatihan Vokasi dan Produktivitas Bandung | C9: Christiana Dewi Rasmawati | D9: Konsumsi Peserta Pelatihan Tailor Made Training (PNBP) | E9: E-Purchasing | F9: BELUM REALISASI | G9: 105600000 | H9: 0 | I9: 0 | J9: Akurat | K9: Sesuai dengan aturan batasan nilai dan metode pengadaan. | L9: Dapat dilanjutkan ke tahap berikutnya.
A10: 63629896 | B10: Balai Besar Pelatihan Vokasi dan Produktivitas Bandung | C10: Christiana Dewi Rasmawati | D10: Pakaian Kerja Project Based Learning | E10: E-Purchasing | F10: PAYMENT_OUTSIDE_SYSTEM | G10: 72000000 | H10: 71757504 | I10: 100 | J10: Akurat | K10: Sesuai dengan aturan batasan nilai dan metode pengadaan. | L10: Dapat dilanjutkan ke tahap berikutnya.
A11: 63629897 | B11: Balai Besar Pelatihan Vokasi dan Produktivitas Bandung | C11: Christiana Dewi Rasmawati | D11: Safety Shoes Project Based Learning | E11: E-Purchasing | F11: BELUM REALISASI | G11: 168000000 | H11: 0 | I11: 0 | J11: Akurat | K11: Sesuai dengan aturan batasan nilai dan metode pengadaan. | L11: Dapat dilanjutkan ke tahap berikutnya.
A12: 63632766 | B12: Balai Besar Pelatihan Vokasi dan Produktivitas Bandung | C12: Christiana Dewi Rasmawati | D12: Safety Shoes PBK Reguler | E12: E-Purchasing | F12: COMPLETED | G12: 145600000 | H12: 39177600 | I12: 27 | J12: Akurat | K12: Sesuai dengan aturan batasan nilai dan metode pengadaan. | L12: Dapat dilanjutkan ke tahap berikutnya.
A13: 63632770 | B13: Balai Besar Pelatihan Vokasi dan Produktivitas Bandung | C13: Christiana Dewi Rasmawati | D13: Konsumsi Peserta Pelatihan Penugasan | E13: E-Purchasing | F13: BELUM REALISASI | G13: 38400000 | H13: 0 | I13: 0 | J13: Akurat | K13: Sesuai dengan aturan batasan nilai dan metode pengadaan. | L13: Dapat dilanjutkan ke tahap berikutnya.
A14: 63633228 | B14: Balai Besar Pelatihan Vokasi dan Produktivitas Bandung | C14: Christiana Dewi Rasmawati | D14: Pakaian Kerja Pelatihan Vokasi yang Mendukung Pekerjaan Hijau (Green Jobs) | E14: E-Purchasing | F14: BELUM REALISASI | G14: 57600000 | H14: 0 | I14: 0 | J14: Akurat | K14: Sesuai dengan aturan batasan nilai dan metode pengadaan. | L14: Dapat dilanjutkan ke tahap berikutnya.
A15: 63633231 | B15: Balai Besar Pelatihan Vokasi dan Produktivitas Bandung | C15: Christiana Dewi Rasmawati | D15: Konsumsi Peserta Pelatihan Vokasi yang Mendukung Pekerjaan Hijau (Green Jobs) | E15: E-Purchasing | F15: BELUM REALISASI | G15: 44800000 | H15: 0 | I15: 0 | J15: Akurat | K15: Metode pengadaan sesuai dengan batasan nilai pagu paket. | L15: Dapat dilanjutkan ke tahap pengadaan berikutnya.
... A159: 67635355 | B159: Balai Besar Pelatihan Vokasi dan Produktivitas Bandung | C159: Christiana Dewi Rasmawati | D159: Operasional Penyelenggaraan Pelatihan Lainnya (Sewa Peralatan Pelatihan) | E159: Pengadaan Langsung | F159: BELUM REALISASI | G159: 64546000 | H159: 0 | I159: 0 | J159: Akurat | K159: Metode Pengadaan Langsung sesuai untuk pengadaan Jasa Lainnya dengan pagu Rp64.546.000 (maksimal Rp200.000.000). | L159: Catatan: Pengadaan Langsung ini wajib menggunakan SPSE fitur transaksional sesuai Perpres 46/2025.
